Workbook

Sheet Sheet1
A1: Part number | B1: Type | C1: Client | D1: First Preview Week | E1: Production Week (W0) | F1: Month | G1: Holliday | H1: Module cost | I1: Registered Vehicles Variation (M-1) | J1: Interest rate (M-1) | K1: Inflation (M-1) | L1: Initial previewed volume | M1: Confirmed volume | N1: Leadtime preview | O1: Volume's cut (Percentage remainder)
A2: C | B2: A | C2: A | D2: =IF(E2-N2<0,E2-N2+52,E2-N2) -> 12 | E2: 27 | F2: =VLOOKUP($E2,Sheet3!$B$3:$D$54,2,0) -> 7 | G2: =VLOOKUP($E2,Sheet3!$B$3:$G$54,3,FALSE) -> 0 | H2: =VLOOKUP($A2,Sheet3!$I$3:$J$38,2,0) -> 27.57 | I2: =VLOOKUP($E2,Sheet3!$B$3:$G$54,5,0) -> 124806 | J2: =VLOOKUP($E2,Sheet3!$B$3:$G$54,4,0) -> 4.5 | K2: =VLOOKUP($E2,Sheet3!$B$3:$G$54,6,0) -> 1.3 | L2: 4770 | M2: 1620 | N2: 15 | O2: =M2/L2 -> 0.33962264
A3: C | B3: A | C3: A | D3: =IF(E3-N3<0,E3-N3+52,E3-N3) -> 12 | E3: 28 | F3: =VLOOKUP($E3,Sheet3!$B$3:$D$54,2,0) -> 7 | G3: =VLOOKUP($E3,Sheet3!$B$3:$G$54,3,FALSE) -> 0 | H3: =VLOOKUP($A3,Sheet3!$I$3:$J$38,2,0) -> 27.57 | I3: =VLOOKUP($E3,Sheet3!$B$3:$G$54,5,0) -> 124806 | J3: =VLOOKUP($E3,Sheet3!$B$3:$G$54,4,0) -> 4.5 | K3: =VLOOKUP($E3,Sheet3!$B$3:$G$54,6,0) -> 1.3 | L3: 4770 | M3: 2070 | N3: 16 | O3: =M3/L3 -> 0.43396226
A4: C | B4: A | C4: A | D4: =IF(E4-N4<0,E4-N4+52,E4-N4) -> 12 | E4: 29 | F4: =VLOOKUP($E4,Sheet3!$B$3:$D$54,2,0) -> 7 | G4: =VLOOKUP($E4,Sheet3!$B$3:$G$54,3,FALSE) -> 0 | H4: =VLOOKUP($A4,Sheet3!$I$3:$J$38,2,0) -> 27.57 | I4: =VLOOKUP($E4,Sheet3!$B$3:$G$54,5,0) -> 124806 | J4: =VLOOKUP($E4,Sheet3!$B$3:$G$54,4,0) -> 4.5 | K4: =VLOOKUP($E4,Sheet3!$B$3:$G$54,6,0) -> 1.3 | L4: 4860 | M4: 2880 | N4: 17 | O4: =M4/L4 -> 0.59259259
A5: C | B5: A | C5: A | D5: =IF(E5-N5<0,E5-N5+52,E5-N5) -> 12 | E5: 30 | F5: =VLOOKUP($E5,Sheet3!$B$3:$D$54,2,0) -> 7 | G5: =VLOOKUP($E5,Sheet3!$B$3:$G$54,3,FALSE) -> 0 | H5: =VLOOKUP($A5,Sheet3!$I$3:$J$38,2,0) -> 27.57 | I5: =VLOOKUP($E5,Sheet3!$B$3:$G$54,5,0) -> 124806 | J5: =VLOOKUP($E5,Sheet3!$B$3:$G$54,4,0) -> 4.5 | K5: =VLOOKUP($E5,Sheet3!$B$3:$G$54,6,0) -> 1.3 | L5: 4770 | M5: 2700 | N5: 18 | O5: =M5/L5 -> 0.56603774
A6: C | B6: A | C6: A | D6: =IF(E6-N6<0,E6-N6+52,E6-N6) -> 12 | E6: 31 | F6: =VLOOKUP($E6,Sheet3!$B$3:$D$54,2,0) -> 7 | G6: =VLOOKUP($E6,Sheet3!$B$3:$G$54,3,FALSE) -> 0 | H6: =VLOOKUP($A6,Sheet3!$I$3:$J$38,2,0) -> 27.57 | I6: =VLOOKUP($E6,Sheet3!$B$3:$G$54,5,0) -> 124806 | J6: =VLOOKUP($E6,Sheet3!$B$3:$G$54,4,0) -> 4.5 | K6: =VLOOKUP($E6,Sheet3!$B$3:$G$54,6,0) -> 1.3 | L6: 3960 | M6: 2790 | N6: 19 | O6: =M6/L6 -> 0.70454545
A7: C | B7: A | C7: A | D7: =IF(E7-N7<0,E7-N7+52,E7-N7) -> 14 | E7: 32 | F7: =VLOOKUP($E7,Sheet3!$B$3:$D$54,2,0) -> 8 | G7: =VLOOKUP($E7,Sheet3!$B$3:$G$54,3,FALSE) -> 1 | H7: =VLOOKUP($A7,Sheet3!$I$3:$J$38,2,0) -> 27.57 | I7: =VLOOKUP($E7,Sheet3!$B$3:$G$54,5,0) -> 69121 | J7: =VLOOKUP($E7,Sheet3!$B$3:$G$54,4,0) -> 4.5 | K7: =VLOOKUP($E7,Sheet3!$B$3:$G$54,6,0) -> 1.1 | L7: 0 | M7: 0 | N7: 18 | O7: =M7/L7 -> #DIV/0!
A8: C | B8: A | C8: A | D8: =IF(E8-N8<0,E8-N8+52,E8-N8) -> 15 | E8: 33 | F8: =VLOOKUP($E8,Sheet3!$B$3:$D$54,2,0) -> 8 | G8: =VLOOKUP($E8,Sheet3!$B$3:$G$54,3,FALSE) -> 1 | H8: =VLOOKUP($A8,Sheet3!$I$3:$J$38,2,0) -> 27.57 | I8: =VLOOKUP($E8,Sheet3!$B$3:$G$54,5,0) -> 69121 | J8: =VLOOKUP($E8,Sheet3!$B$3:$G$54,4,0) -> 4.5 | K8: =VLOOKUP($E8,Sheet3!$B$3:$G$54,6,0) -> 1.1 | L8: 0 | M8: 0 | N8: 18 | O8: =M8/L8 -> #DIV/0!
A9: C | B9: A | C9: A | D9: =IF(E9-N9<0,E9-N9+52,E9-N9) -> 15 | E9: 34 | F9: =VLOOKUP($E9,Sheet3!$B$3:$D$54,2,0) -> 8 | G9: =VLOOKUP($E9,Sheet3!$B$3:$G$54,3,FALSE) -> 0 | H9: =VLOOKUP($A9,Sheet3!$I$3:$J$38,2,0) -> 27.57 | I9: =VLOOKUP($E9,Sheet3!$B$3:$G$54,5,0) -> 69121 | J9: =VLOOKUP($E9,Sheet3!$B$3:$G$54,4,0) -> 4.5 | K9: =VLOOKUP($E9,Sheet3!$B$3:$G$54,6,0) -> 1.1 | L9: 2880 | M9: 0 | N9: 19 | O9: =M9/L9 -> 0
A10: C | B10: A | C10: A | D10: =IF(E10-N10<0,E10-N10+52,E10-N10) -> 15 | E10: 35 | F10: =VLOOKUP($E10,Sheet3!$B$3:$D$54,2,0) -> 8 | G10: =VLOOKUP($E10,Sheet3!$B$3:$G$54,3,0) -> 0 | H10: =VLOOKUP($A10,Sheet3!$I$3:$J$38,2,0) -> 27.57 | I10: =VLOOKUP($E10,Sheet3!$B$3:$G$54,5,0) -> 69121 | J10: =VLOOKUP($E10,Sheet3!$B$3:$G$54,4,0) -> 4.5 | K10: =VLOOKUP($E10,Sheet3!$B$3:$G$54,6,0) -> 1.1 | L10: 3586 | M10: 3420 | N10: 20 | O10: =M10/L10 -> 0.95370887
A11: C | B11: A | C11: A | D11: =IF(E11-N11<0,E11-N11+52,E11-N11) -> 23 | E11: 36 | F11: =VLOOKUP($E11,Sheet3!$B$3:$D$54,2,0) -> 9 | G11: =VLOOKUP($E11,Sheet3!$B$3:$G$54,3,0) -> 0 | H11: =VLOOKUP($A11,Sheet3!$I$3:$J$38,2,0) -> 27.57 | I11: =VLOOKUP($E11,Sheet3!$B$3:$G$54,5,0) -> 121666 | J11: =VLOOKUP($E11,Sheet3!$B$3:$G$54,4,0) -> 4.5 | K11: =VLOOKUP($E11,Sheet3!$B$3:$G$54,6,0) -> 0.7 | L11: 4680 | M11: 3240 | N11: 13 | O11: =M11/L11 -> 0.69230769
A12: C | B12: A | C12: A | D12: =IF(E12-N12<0,E12-N12+52,E12-N12) -> 23 | E12: 37 | F12: =VLOOKUP($E12,Sheet3!$B$3:$D$54,2,0) -> 9 | G12: =VLOOKUP($E12,Sheet3!$B$3:$G$54,3,0) -> 0 | H12: =VLOOKUP($A12,Sheet3!$I$3:$J$38,2,0) -> 27.57 | I12: =VLOOKUP($E12,Sheet3!$B$3:$G$54,5,0) -> 121666 | J12: =VLOOKUP($E12,Sheet3!$B$3:$G$54,4,0) -> 4.5 | K12: =VLOOKUP($E12,Sheet3!$B$3:$G$54,6,0) -> 0.7 | L12: 4770 | M12: 2340 | N12: 14 | O12: =M12/L12 -> 0.49056604
A13: C | B13: A | C13: A | D13: =IF(E13-N13<0,E13-N13+52,E13-N13) -> 23 | E13: 38 | F13: =VLOOKUP($E13,Sheet3!$B$3:$D$54,2,0) -> 9 | G13: =VLOOKUP($E13,Sheet3!$B$3:$G$54,3,0) -> 0 | H13: =VLOOKUP($A13,Sheet3!$I$3:$J$38,2,0) -> 27.57 | I13: =VLOOKUP($E13,Sheet3!$B$3:$G$54,5,0) -> 121666 | J13: =VLOOKUP($E13,Sheet3!$B$3:$G$54,4,0) -> 3.9 | K13: =VLOOKUP($E13,Sheet3!$B$3:$G$54,6,0) -> 0.7 | L13: 3600 | M13: 3960 | N13: 15 | O13: =M13/L13 -> 1.1
A14: C | B14: A | C14: A | D14: =IF(E14-N14<0,E14-N14+52,E14-N14) -> 23 | E14: 39 | F14: =VLOOKUP($E14,Sheet3!$B$3:$D$54,2,0) -> 9 | G14: =VLOOKUP($E14,Sheet3!$B$3:$G$54,3,0) -> 0 | H14: =VLOOKUP($A14,Sheet3!$I$3:$J$38,2,0) -> 27.57 | I14: =VLOOKUP($E14,Sheet3!$B$3:$G$54,5,0) -> 121666 | J14: =VLOOKUP($E14,Sheet3!$B$3:$G$54,4,0) -> 3.9 | K14: =VLOOKUP($E14,Sheet3!$B$3:$G$54,6,0) -> 0.7 | L14: 3600 | M14: 3690 | N14: 16 | O14: =M14/L14 -> 1.025
A15: C | B15: A | C15: A | D15: =IF(E15-N15<0,E15-N15+52,E15-N15) -> 27 | E15: 40 | F15: =VLOOKUP($E15,Sheet3!$B$3:$D$54,2,0) -> 9 | G15: =VLOOKUP($E15,Sheet3!$B$3:$G$54,3,0) -> 0 | H15: =VLOOKUP($A15,Sheet3!$I$3:$J$38,2,0) -> 27.57 | I15: =VLOOKUP($E15,Sheet3!$B$3:$G$54,5,0) -> 121666 | J15: =VLOOKUP($E15,Sheet3!$B$3:$G$54,4,0) -> 3.9 | K15: =VLOOKUP($E15,Sheet3!$B$3:$G$54,6,0) -> 0.7 | L15: 3600 | M15: 2520 | N15: 13 | O15: =M15/L15 -> 0.7
A16: C | B16: A | C16: A | D16: =IF(E16-N16<0,E16-N16+52,E16-N16) -> 27 | E16: 41 | F16: =VLOOKUP($E16,Sheet3!$B$3:$D$54,2,0) -> 10 | G16: =VLOOKUP($E16,Sheet3!$B$3:$G$54,3,0) -> 0 | H16: =VLOOKUP($A16,Sheet3!$I$3:$J$38,2,0) -> 27.57 | I16: =VLOOKUP($E16,Sheet3!$B$3:$G$54,5,0) -> 126488 | J16: =VLOOKUP($E16,Sheet3!$B$3:$G$54,4,0) -> 3.9 | K16: =VLOOKUP($E16,Sheet3!$B$3:$G$54,6,0) -> 0.9 | L16: 3600 | M16: 1080 | N16: 14 | O16: =M16/L16 -> 0.3
A17: C | B17: A | C17: A | D17: =IF(E17-N17<0,E17-N17+52,E17-N17) -> 27 | E17: 42 | F17: =VLOOKUP($E17,Sheet3!$B$3:$D$54,2,0) -> 10 | G17: =VLOOKUP($E17,Sheet3!$B$3:$G$54,3,0) -> 0 | H17: =VLOOKUP($A17,Sheet3!$I$3:$J$38,2,0) -> 27.57 | I17: =VLOOKUP($E17,Sheet3!$B$3:$G$54,5,0) -> 126488 | J17: =VLOOKUP($E17,Sheet3!$B$3:$G$54,4,0) -> 3.9 | K17: =VLOOKUP($E17,Sheet3!$B$3:$G$54,6,0) -> 0.9 | L17: 3600 | M17: 2250 | N17: 15 | O17: =M17/L17 -> 0.625
A18: C | B18: A | C18: A | D18: =IF(E18-N18<0,E18-N18+52,E18-N18) -> 27 | E18: 43 | F18: =VLOOKUP($E18,Sheet3!$B$3:$D$54,2,0) -> 10 | G18: =VLOOKUP($E18,Sheet3!$B$3:$G$54,3,0) -> 0 | H18: =VLOOKUP($A18,Sheet3!$I$3:$J$38,2,0) -> 27.57 | I18: =VLOOKUP($E18,Sheet3!$B$3:$G$54,5,0) -> 126488 | J18: =VLOOKUP($E18,Sheet3!$B$3:$G$54,4,0) -> 3.65 | K18: =VLOOKUP($E18,Sheet3!$B$3:$G$54,6,0) -> 0.9 | L18: 3600 | M18: 2700 | N18: 16 | O18: =M18/L18 -> 0.75
A19: C | B19: A | C19: A | D19: =IF(E19-N19<0,E19-N19+52,E19-N19) -> 27 | E19: 44 | F19: =VLOOKUP($E19,Sheet3!$B$3:$D$54,2,0) -> 10 | G19: =VLOOKUP($E19,Sheet3!$B$3:$G$54,3,0) -> 1 | H19: =VLOOKUP($A19,Sheet3!$I$3:$J$38,2,0) -> 27.57 | I19: =VLOOKUP($E19,Sheet3!$B$3:$G$54,5,0) -> 126488 | J19: =VLOOKUP($E19,Sheet3!$B$3:$G$54,4,0) -> 3.65 | K19: =VLOOKUP($E19,Sheet3!$B$3:$G$54,6,0) -> 0.9 | L19: 2430 | M19: 0 | N19: 17 | O19: =M19/L19 -> 0
A20: C | B20: A | C20: A | D20: =IF(E20-N20<0,E20-N20+52,E20-N20) -> 36 | E20: 45 | F20: =VLOOKUP($E20,Sheet3!$B$3:$D$54,2,0) -> 11 | G20: =VLOOKUP($E20,Sheet3!$B$3:$G$54,3,0) -> 0 | H20: =VLOOKUP($A20,Sheet3!$I$3:$J$38,2,0) -> 27.57 | I20: =VLOOKUP($E20,Sheet3!$B$3:$G$54,5,0) -> 124251 | J20: =VLOOKUP($E20,Sheet3!$B$3:$G$54,4,0) -> 3.65 | K20: =VLOOKUP($E20,Sheet3!$B$3:$G$54,6,0) -> 1.3 | L20: 3060 | M20: 2610 | N20: 9 | O20: =M20/L20 -> 0.85294118
A21: C | B21: A | C21: A | D21: =IF(E21-N21<0,E21-N21+52,E21-N21) -> 36 | E21: 46 | F21: =VLOOKUP($E21,Sheet3!$B$3:$D$54,2,0) -> 11 | G21: =VLOOKUP($E21,Sheet3!$B$3:$G$54,3,0) -> 0 | H21: =VLOOKUP($A21,Sheet3!$I$3:$J$38,2,0) -> 27.57 | I21: =VLOOKUP($E21,Sheet3!$B$3:$G$54,5,0) -> 124251 | J21: =VLOOKUP($E21,Sheet3!$B$3:$G$54,4,0) -> 3.65 | K21: =VLOOKUP($E21,Sheet3!$B$3:$G$54,6,0) -> 1.3 | L21: 3060 | M21: 2970 | N21: 10 | O21: =M21/L21 -> 0.97058824
... A1093: I | B1093: B | C1093: E | D1093: =IF(E1093-N1093<0,E1093-N1093+52,E1093-N1093) -> 7 | E1093: 26 | F1093: =VLOOKUP($E1093,Sheet3!$B$3:$D$54,2,0) -> 6 | G1093: =VLOOKUP($E1093,Sheet3!$B$3:$G$54,3,0) -> 0 | H1093: =VLOOKUP($A1093,Sheet3!$I$3:$J$38,2,0) -> 17.47 | I1093: =VLOOKUP($E1093,Sheet3!$B$3:$G$54,5,0) -> 132191 | J1093: =VLOOKUP($E1093,Sheet3!$B$3:$G$54,4,0) -> 2.4 | K1093: =VLOOKUP($E1093,Sheet3!$B$3:$G$54,6,0) -> 1.7 | L1093: 1376 | M1093: 560 | N1093: 19 | O1093: =M1093/L1093 -> 0.40697674

Sheet Sheet3
A1: Calender | B1: Calender | C1: Calender | D1: Calender | E1: ECB | F1: Federauto | G1: Trading Economics | I1: SAP ZMCALCOS | J1: SAP ZMCALCOS | L1: Federauto | M1: Federauto | N1: Federauto | O1: Trading Economics
A2: Year | B2: Week | C2: Month | D2: Holliday | E2: Interest rate | F2: Regist. Vehicles | G2: Inflation | I2: Module | J2: Cost | L2: Month/Year | M2: Month | N2: Registered | O2: Inflation
A3: 2024 | B3: 27 | C3: 7 | D3: 0 | E3: 4.5 | F3: =VLOOKUP($C3,$M$3:$N$14,2,0) -> 124806 | G3: 1.3 | I3: A | J3: 19.29 | L3: 45474 | M3: 7 | N3: 124806 | O3: 1.3
A4: 2024 | B4: 28 | C4: 7 | D4: 0 | E4: 4.5 | F4: =VLOOKUP($C4,$M$3:$N$14,2,0) -> 124806 | G4: 1.3 | I4: B | J4: 29.53 | L4: 45505 | M4: 8 | N4: 69121 | O4: 1.1
A5: 2024 | B5: 29 | C5: 7 | D5: 0 | E5: 4.5 | F5: =VLOOKUP($C5,$M$3:$N$14,2,0) -> 124806 | G5: 1.3 | I5: C | J5: 27.57 | L5: 45536 | M5: 9 | N5: 121666 | O5: 0.7
A6: 2024 | B6: 30 | C6: 7 | D6: 0 | E6: 4.5 | F6: =VLOOKUP($C6,$M$3:$N$14,2,0) -> 124806 | G6: 1.3 | I6: D | J6: 23.37 | L6: 45566 | M6: 10 | N6: 126488 | O6: 0.9
A7: 2024 | B7: 31 | C7: 7 | D7: 0 | E7: 4.5 | F7: =VLOOKUP($C7,$M$3:$N$14,2,0) -> 124806 | G7: 1.3 | I7: E | J7: 19.18 | L7: 45597 | M7: 11 | N7: 124251 | O7: 1.3
A8: 2024 | B8: 32 | C8: 8 | D8: 1 | E8: 4.5 | F8: =VLOOKUP($C8,$M$3:$N$14,2,0) -> 69121 | G8: 1.1 | I8: F | J8: 29.17 | L8: 45627 | M8: 12 | N8: 105715 | O8: 1.3
A9: 2024 | B9: 33 | C9: 8 | D9: 1 | E9: 4.5 | F9: =VLOOKUP($C9,$M$3:$N$14,2,0) -> 69121 | G9: 1.1 | I9: G | J9: 23.6 | L9: 45658 | M9: 1 | N9: 133692 | O9: 1.5
A10: 2024 | B10: 34 | C10: 8 | D10: 0 | E10: 4.5 | F10: =VLOOKUP($C10,$M$3:$N$14,2,0) -> 69121 | G10: 1.1 | I10: H | J10: 12.72 | L10: 45689 | M10: 2 | N10: 137922 | O10: 1.6
A11: 2024 | B11: 35 | C11: 8 | D11: 0 | E11: 4.5 | F11: =VLOOKUP($C11,$M$3:$N$14,2,0) -> 69121 | G11: 1.1 | I11: I | J11: 17.47 | L11: 45717 | M11: 3 | N11: 172223 | O11: 1.9
A12: 2024 | B12: 36 | C12: 9 | D12: 0 | E12: 4.5 | F12: =VLOOKUP($C12,$M$3:$N$14,2,0) -> 121666 | G12: 0.7 | I12: J | J12: 24.18 | L12: 45748 | M12: 4 | N12: 139084 | O12: 1.9
A13: 2024 | B13: 37 | C13: 9 | D13: 0 | E13: 4.5 | F13: =VLOOKUP($C13,$M$3:$N$14,2,0) -> 121666 | G13: 0.7 | I13: K | J13: 18.5 | L13: 45778 | M13: 5 | N13: 139390 | O13: 1.6
A14: 2024 | B14: 38 | C14: 9 | D14: 0 | E14: 3.9 | F14: =VLOOKUP($C14,$M$3:$N$14,2,0) -> 121666 | G14: 0.7 | I14: L | J14: 21.88 | L14: 45809 | M14: 6 | N14: 132191 | O14: 1.7
A15: 2024 | B15: 39 | C15: 9 | D15: 0 | E15: 3.9 | F15: =VLOOKUP($C15,$M$3:$N$14,2,0) -> 121666 | G15: 0.7 | I15: M | J15: 21.63
A16: 2024 | B16: 40 | C16: 9 | D16: 0 | E16: 3.9 | F16: =VLOOKUP($C16,$M$3:$N$14,2,0) -> 121666 | G16: 0.7 | I16: N | J16: 10.1
A17: 2024 | B17: 41 | C17: 10 | D17: 0 | E17: 3.9 | F17: =VLOOKUP($C17,$M$3:$N$14,2,0) -> 126488 | G17: 0.9 | I17: O | J17: 22.25
A18: 2024 | B18: 42 | C18: 10 | D18: 0 | E18: 3.9 | F18: =VLOOKUP($C18,$M$3:$N$14,2,0) -> 126488 | G18: 0.9 | I18: P | J18: 18.1
A19: 2024 | B19: 43 | C19: 10 | D19: 0 | E19: 3.65 | F19: =VLOOKUP($C19,$M$3:$N$14,2,0) -> 126488 | G19: 0.9 | I19: Q | J19: 26.39
A20: 2024 | B20: 44 | C20: 10 | D20: 1 | E20: 3.65 | F20: =VLOOKUP($C20,$M$3:$N$14,2,0) -> 126488 | G20: 0.9 | I20: R | J20: 17.2
A21: 2024 | B21: 45 | C21: 11 | D21: 0 | E21: 3.65 | F21: =VLOOKUP($C21,$M$3:$N$14,2,0) -> 124251 | G21: 1.3 | I21: S | J21: 17.53
A22: 2024 | B22: 46 | C22: 11 | D22: 0 | E22: 3.65 | F22: =VLOOKUP($C22,$M$3:$N$14,2,0) -> 124251 | G22: 1.3 | I22: T | J22: 26.77
A23: 2024 | B23: 47 | C23: 11 | D23: 0 | E23: 3.65 | F23: =VLOOKUP($C23,$M$3:$N$14,2,0) -> 124251 | G23: 1.3 | I23: U | J23: 17.21
A24: 2024 | B24: 48 | C24: 11 | D24: 0 | E24: 3.65 | F24: =VLOOKUP($C24,$M$3:$N$14,2,0) -> 124251 | G24: 1.3
A25: 2024 | B25: 49 | C25: 12 | D25: 1 | E25: 3.65 | F25: =VLOOKUP($C25,$M$3:$N$14,2,0) -> 105715 | G25: 1.3
A26: 2024 | B26: 50 | C26: 12 | D26: 0 | E26: 3.4 | F26: =VLOOKUP($C26,$M$3:$N$14,2,0) -> 105715 | G26: 1.3
A27: 2024 | B27: 51 | C27: 12 | D27: 0 | E27: 3.4 | F27: =VLOOKUP($C27,$M$3:$N$14,2,0) -> 105715 | G27: 1.3
A28: 2024 | B28: 52 | C28: 12 | D28: 1 | E28: 3.4 | F28: =VLOOKUP($C28,$M$3:$N$14,2,0) -> 105715 | G28: 1.3
A29: 2025 | B29: 1 | C29: 12 | D29: 1 | E29: 3.4 | F29: =VLOOKUP($C29,$M$3:$N$14,2,0) -> 105715 | G29: 1.3
A30: 2025 | B30: 2 | C30: 1 | D30: 1 | E30: 3.4 | F30: =VLOOKUP($C30,$M$3:$N$14,2,0) -> 133692 | G30: 1.5
A31: 2025 | B31: 3 | C31: 1 | D31: 0 | E31: 3.4 | F31: =VLOOKUP($C31,$M$3:$N$14,2,0) -> 133692 | G31: 1.5
A32: 2025 | B32: 4 | C32: 1 | D32: 0 | E32: 3.4 | F32: =VLOOKUP($C32,$M$3:$N$14,2,0) -> 133692 | G32: 1.5
A33: 2025 | B33: 5 | C33: 1 | D33: 0 | E33: 3.4 | F33: =VLOOKUP($C33,$M$3:$N$14,2,0) -> 133692 | G33: 1.5
A34: 2025 | B34: 6 | C34: 2 | D34: 0 | E34: 3.15 | F34: =VLOOKUP($C34,$M$3:$N$14,2,0) -> 137922 | G34: 1.6
A35: 2025 | B35: 7 | C35: 2 | D35: 0 | E35: 3.15 | F35: =VLOOKUP($C35,$M$3:$N$14,2,0) -> 137922 | G35: 1.6
... A54: 2025 | B54: 26 | C54: 6 | D54: 0 | E54: 2.4 | F54: =VLOOKUP($C54,$M$3:$N$14,2,0) -> 132191 | G54: 1.7

Sheet Final
A1: Part number | B1: Type | C1: Client | D1: First Preview Week | E1: Production Week (W0) | F1: Month | G1: Holliday | H1: Module cost | I1: Registered Vehicles Variation (M-1) | J1: Interest rate (M-1) | K1: Inflation (M-1) | L1: Initial previewed volume | M1: Confirmed volume | N1: Leadtime preview | O1: Volume's cut (Percentage remainder)
A2: C | B2: A | C2: A | D2: 12 | E2: 27 | F2: 7 | G2: FALSE | H2: 17.25 | I2: 124806 | J2: 4.5 | K2: 1.3 | L2: 4770 | M2: 1620 | N2: 15 | O2: 0.33962264
A3: C | B3: A | C3: A | D3: 12 | E3: 28 | F3: 7 | G3: FALSE | H3: 17.25 | I3: 124806 | J3: 4.5 | K3: 1.3 | L3: 4770 | M3: 2070 | N3: 16 | O3: 0.43396226
A4: C | B4: A | C4: A | D4: 12 | E4: 29 | F4: 7 | G4: FALSE | H4: 17.25 | I4: 124806 | J4: 4.5 | K4: 1.3 | L4: 4860 | M4: 2880 | N4: 17 | O4: 0.59259259
A5: C | B5: A | C5: A | D5: 12 | E5: 30 | F5: 7 | G5: FALSE | H5: 17.25 | I5: 124806 | J5: 4.5 | K5: 1.3 | L5: 4770 | M5: 2700 | N5: 18 | O5: 0.56603774
A6: C | B6: A | C6: A | D6: 12 | E6: 31 | F6: 7 | G6: FALSE | H6: 17.25 | I6: 124806 | J6: 4.5 | K6: 1.3 | L6: 3960 | M6: 2790 | N6: 19 | O6: 0.70454545
A7: C | B7: A | C7: A | D7: 14 | E7: 32 | F7: 8 | G7: TRUE | H7: 17.25 | I7: 69121 | J7: 4.5 | K7: 1.1 | L7: 0 | M7: 0 | N7: 18 | O7: #DIV/0!
A8: C | B8: A | C8: A | D8: 15 | E8: 33 | F8: 8 | G8: TRUE | H8: 17.25 | I8: 69121 | J8: 4.5 | K8: 1.1 | L8: 0 | M8: 0 | N8: 18 | O8: #DIV/0!
A9: C | B9: A | C9: A | D9: 15 | E9: 34 | F9: 8 | G9: FALSE | H9: 17.25 | I9: 69121 | J9: 4.5 | K9: 1.1 | L9: 2880 | M9: 0 | N9: 19 | O9: 0
A10: C | B10: A | C10: A | D10: 15 | E10: 35 | F10: 8 | G10: FALSE | H10: 17.25 | I10: 69121 | J10: 4.5 | K10: 1.1 | L10: 3586 | M10: 3420 | N10: 20 | O10: 0.95370887
A11: C | B11: A | C11: A | D11: 23 | E11: 36 | F11: 9 | G11: FALSE | H11: 17.25 | I11: 121666 | J11: 4.5 | K11: 0.7 | L11: 4680 | M11: 3240 | N11: 13 | O11: 0.69230769
A12: C | B12: A | C12: A | D12: 23 | E12: 37 | F12: 9 | G12: FALSE | H12: 17.25 | I12: 121666 | J12: 4.5 | K12: 0.7 | L12: 4770 | M12: 2340 | N12: 14 | O12: 0.49056604
A13: C | B13: A | C13: A | D13: 23 | E13: 38 | F13: 9 | G13: FALSE | H13: 17.25 | I13: 121666 | J13: 3.9 | K13: 0.7 | L13: 3600 | M13: 3960 | N13: 15 | O13: 1.1
A14: C | B14: A | C14: A | D14: 23 | E14: 39 | F14: 9 | G14: FALSE | H14: 17.25 | I14: 121666 | J14: 3.9 | K14: 0.7 | L14: 3600 | M14: 3690 | N14: 16 | O14: 1.025
A15: C | B15: A | C15: A | D15: 27 | E15: 40 | F15: 9 | G15: FALSE | H15: 17.25 | I15: 121666 | J15: 3.9 | K15: 0.7 | L15: 3600 | M15: 2520 | N15: 13 | O15: 0.7
A16: C | B16: A | C16: A | D16: 27 | E16: 41 | F16: 10 | G16: FALSE | H16: 17.25 | I16: 126488 | J16: 3.9 | K16: 0.9 | L16: 3600 | M16: 1080 | N16: 14 | O16: 0.3
A17: C | B17: A | C17: A | D17: 27 | E17: 42 | F17: 10 | G17: FALSE | H17: 17.25 | I17: 126488 | J17: 3.9 | K17: 0.9 | L17: 3600 | M17: 2250 | N17: 15 | O17: 0.625
A18: C | B18: A | C18: A | D18: 27 | E18: 43 | F18: 10 | G18: FALSE | H18: 17.25 | I18: 126488 | J18: 3.65 | K18: 0.9 | L18: 3600 | M18: 2700 | N18: 16 | O18: 0.75
A19: C | B19: A | C19: A | D19: 27 | E19: 44 | F19: 10 | G19: TRUE | H19: 17.25 | I19: 126488 | J19: 3.65 | K19: 0.9 | L19: 2430 | M19: 0 | N19: 17 | O19: 0
A20: C | B20: A | C20: A | D20: 36 | E20: 45 | F20: 11 | G20: FALSE | H20: 17.25 | I20: 124251 | J20: 3.65 | K20: 1.3 | L20: 3060 | M20: 2610 | N20: 9 | O20: 0.85294118
... A28: C | B28: A | C28: A | D28: 41 | E28: 1 | F28: 12 | G28: TRUE | H28: 17.25 | I28: 105715 | J28: 3.4 | K28: 1.3 | L28: 3060 | M28: 0 | N28: 12 | O28: 0
A29: C | B29: A | C29: A | D29: 42 | E29: 2 | F29: 1 | G29: TRUE | H29: 17.25 | I29: 133692 | J29: 3.4 | K29: 1.5 | L29: 0 | M29: 0 | N29: 12 | O29: #DIV/0!
A30: C | B30: A | C30: A | D30: 43 | E30: 3 | F30: 1 | G30: FALSE | H30: 17.25 | I30: 133692 | J30: 3.4 | K30: 1.5 | L30: 3690 | M30: 1440 | N30: 12 | O30: 0.3902439
A31: C | B31: A | C31: A | D31: 43 | E31: 4 | F31: 1 | G31: FALSE | H31: 17.25 | I31: 133692 | J31: 3.4 | K31: 1.5 | L31: 3600 | M31: 2340 | N31: 13 | O31: 0.65
A32: C | B32: A | C32: A | D32: 43 | E32: 5 | F32: 1 | G32: FALSE | H32: 17.25 | I32: 133692 | J32: 3.4 | K32: 1.5 | L32: 3690 | M32: 0 | N32: 14 | O32: 0
A33: C | B33: A | C33: A | D33: 49 | E33: 6 | F33: 2 | G33: FALSE | H33: 17.25 | I33: 137922 | J33: 3.15 | K33: 1.6 | L33: 2430 | M33: 3690 | N33: 9 | O33: 1.5185185
A34: C | B34: A | C34: A | D34: 49 | E34: 7 | F34: 2 | G34: FALSE | H34: 17.25 | I34: 137922 | J34: 3.15 | K34: 1.6 | L34: 2520 | M34: 3330 | N34: 10 | O34: 1.3214286
A35: C | B35: A | C35: A | D35: 49 | E35: 8 | F35: 2 | G35: FALSE | H35: 17.25 | I35: 137922 | J35: 3.15 | K35: 1.6 | L35: 2430 | M35: 3510 | N35: 11 | O35: 1.4444444
A36: C | B36: A | C36: A | D36: 49 | E36: 9 | F36: 2 | G36: FALSE | H36: 17.25 | I36: 137922 | J36: 3.15 | K36: 1.6 | L36: 2520 | M36: 3420 | N36: 12 | O36: 1.3571429
A37: C | B37: A | C37: A | D37: 1 | E37: 10 | F37: 3 | G37: FALSE | H37: 17.25 | I37: 172223 | J37: 3.15 | K37: 1.9 | L37: 2070 | M37: 3060 | N37: 9 | O37: 1.4782609
A38: C | B38: A | C38: A | D38: 1 | E38: 11 | F38: 3 | G38: FALSE | H38: 17.25 | I38: 172223 | J38: 2.9 | K38: 1.9 | L38: 2160 | M38: 2880 | N38: 10 | O38: 1.3333333
A39: C | B39: A | C39: A | D39: 1 | E39: 12 | F39: 3 | G39: FALSE | H39: 17.25 | I39: 172223 | J39: 2.9 | K39: 1.9 | L39: 2160 | M39: 3780 | N39: 11 | O39: 1.75
A40: C | B40: A | C40: A | D40: 1 | E40: 13 | F40: 3 | G40: FALSE | H40: 17.25 | I40: 172223 | J40: 2.9 | K40: 1.9 | L40: 2160 | M40: 3780 | N40: 12 | O40: 1.75
A41: C | B41: A | C41: A | D41: 1 | E41: 14 | F41: 3 | G41: FALSE | H41: 17.25 | I41: 172223 | J41: 2.9 | K41: 1.9 | L41: 1620 | M41: 2790 | N41: 13 | O41: 1.7222222
... A43: C | B43: A | C43: A | D43: 5 | E43: 16 | F43: 4 | G43: FALSE | H43: 17.25 | I43: 139084 | J43: 2.9 | K43: 1.9 | L43: 1530 | M43: 2430 | N43: 11 | O43: 1.5882353
A44: C | B44: A | C44: A | D44: 5 | E44: 17 | F44: 4 | G44: TRUE | H44: 17.25 | I44: 139084 | J44: 2.65 | K44: 1.9 | L44: 0 | M44: 1800 | N44: 12 | O44: #DIV/0!
A45: C | B45: A | C45: A | D45: 6 | E45: 18 | F45: 4 | G45: TRUE | H45: 17.25 | I45: 139084 | J45: 2.65 | K45: 1.9 | L45: 1890 | M45: 2160 | N45: 12 | O45: 1.1428571
A46: C | B46: A | C46: A | D46: 7 | E46: 19 | F46: 5 | G46: FALSE | H46: 17.25 | I46: 139390 | J46: 2.65 | K46: 1.6 | L46: 2790 | M46: 2790 | N46: 12 | O46: 1
A47: C | B47: A | C47: A | D47: 7 | E47: 20 | F47: 5 | G47: FALSE | H47: 17.25 | I47: 139390 | J47: 2.65 | K47: 1.6 | L47: 1080 | M47: 3330 | N47: 13 | O47: 3.0833333
A48: C | B48: A | C48: A | D48: 7 | E48: 21 | F48: 5 | G48: FALSE | H48: 17.25 | I48: 139390 | J48: 2.65 | K48: 1.6 | L48: 2520 | M48: 3420 | N48: 14 | O48: 1.3571429
...
